Workbook

Sheet Data Collection
A2: Period: Q1 2021 - Q4 2025 (20 Quarters)
A4: Quarter | B4: HDFC Bank | C4: ICICI Bank | D4: SBI | E4: Axis Bank | F4: TCS | G4: Infosys | H4: ITC | I4: Titan | J4: Sun Pharma | K4: M&M | L4: Maruti | M4: Reliance | N4: Bharti Airtel | O4: Nifty 50 | Q4: Source
A5: Q1 2021 | B5: 0.045 | C5: 0.068 | D5: 0.125 | E5: 0.052 | F5: 0.035 | G5: 0.042 | H5: 0.065 | I5: 0.078 | J5: 0.072 | K5: 0.145 | L5: 0.055 | M5: 0.048 | N5: 0.085 | O5: 0.052 | Q5: =HYPERLINK("https://www.niftyindices.com/market-data/return-profile") -> https://www.niftyindices.com/market-data/return-profile
A6: Q2 2021 | B6: 0.082 | C6: 0.095 | D6: 0.145 | E6: 0.078 | F6: 0.058 | G6: 0.065 | H6: 0.088 | I6: 0.105 | J6: 0.095 | K6: 0.178 | L6: 0.082 | M6: 0.072 | N6: 0.112 | O6: 0.076 | Q6: =HYPERLINK("https://www.niftyindices.com/market-data/return-profile") -> https://www.niftyindices.com/market-data/return-profile
A7: Q3 2021 | B7: 0.038 | C7: 0.042 | D7: 0.065 | E7: 0.035 | F7: 0.022 | G7: 0.028 | H7: 0.055 | I7: 0.062 | J7: 0.058 | K7: 0.095 | L7: 0.038 | M7: 0.032 | N7: 0.068 | O7: 0.118 | Q7: =HYPERLINK("https://www.niftyindices.com/market-data/return-profile") -> https://www.niftyindices.com/market-data/return-profile
A8: Q4 2021 | B8: 0.056 | C8: 0.072 | D8: 0.098 | E8: 0.062 | F8: 0.045 | G8: 0.052 | H8: 0.072 | I8: 0.088 | J8: 0.082 | K8: 0.128 | L8: 0.065 | M8: 0.058 | N8: 0.095 | O8: -0.015 | Q8: =HYPERLINK("https://www.niftyindices.com/market-data/return-profile") -> https://www.niftyindices.com/market-data/return-profile
A9: Q1 2022 | B9: -0.028 | C9: -0.035 | D9: -0.045 | E9: -0.042 | F9: -0.055 | G9: -0.062 | H9: -0.018 | I9: -0.048 | J9: -0.025 | K9: -0.065 | L9: -0.048 | M9: -0.055 | N9: -0.032 | O9: 0.008 | Q9: =HYPERLINK("https://www.niftyindices.com/market-data/return-profile") -> https://www.niftyindices.com/market-data/return-profile
A10: Q2 2022 | B10: -0.065 | C10: -0.078 | D10: -0.082 | E10: -0.075 | F10: -0.088 | G10: -0.095 | H10: -0.042 | I10: -0.085 | J10: -0.052 | K10: -0.108 | L10: -0.082 | M10: -0.088 | N10: -0.065 | O10: -0.091 | Q10: =HYPERLINK("https://www.niftyindices.com/market-data/return-profile") -> https://www.niftyindices.com/market-data/return-profile
A11: Q3 2022 | B11: 0.072 | C11: 0.088 | D11: 0.115 | E11: 0.082 | F11: 0.042 | G11: 0.048 | H11: 0.078 | I11: 0.095 | J11: 0.085 | K11: 0.152 | L11: 0.072 | M11: 0.065 | N11: 0.098 | O11: 0.085 | Q11: =HYPERLINK("https://www.niftyindices.com/market-data/return-profile") -> https://www.niftyindices.com/market-data/return-profile
A12: Q4 2022 | B12: 0.048 | C12: 0.065 | D12: 0.088 | E12: 0.055 | F12: 0.028 | G12: 0.035 | H12: 0.062 | I12: 0.072 | J12: 0.068 | K12: 0.115 | L12: 0.052 | M12: 0.045 | N12: 0.078 | O12: 0.06 | Q12: =HYPERLINK("https://www.niftyindices.com/market-data/return-profile") -> https://www.niftyindices.com/market-data/return-profile
A13: Q1 2023 | B13: -0.015 | C13: -0.022 | D13: -0.028 | E13: -0.025 | F13: -0.032 | G13: -0.038 | H13: 0.008 | I13: -0.015 | J13: 0.005 | K13: -0.035 | L13: -0.028 | M13: -0.035 | N13: -0.008 | O13: -0.041 | Q13: =HYPERLINK("https://www.niftyindices.com/market-data/return-profile") -> https://www.niftyindices.com/market-data/return-profile
A14: Q2 2023 | B14: 0.062 | C14: 0.075 | D14: 0.095 | E14: 0.068 | F14: 0.038 | G14: 0.045 | H14: 0.072 | I14: 0.082 | J14: 0.078 | K14: 0.125 | L14: 0.062 | M14: 0.055 | N14: 0.088 | O14: 0.102 | Q14: =HYPERLINK("https://www.niftyindices.com/market-data/return-profile") -> https://www.niftyindices.com/market-data/return-profile
A15: Q3 2023 | B15: 0.035 | C15: 0.048 | D15: 0.072 | E15: 0.042 | F15: 0.018 | G15: 0.025 | H15: 0.058 | I15: 0.065 | J15: 0.062 | K15: 0.098 | L15: 0.045 | M15: 0.038 | N15: 0.072 | O15: 0.024 | Q15: =HYPERLINK("https://www.niftyindices.com/market-data/return-profile") -> https://www.niftyindices.com/market-data/return-profile
A16: Q4 2023 | B16: 0.078 | C16: 0.092 | D16: 0.118 | E16: 0.085 | F16: 0.052 | G16: 0.058 | H16: 0.085 | I16: 0.098 | J16: 0.092 | K16: 0.155 | L16: 0.078 | M16: 0.068 | N16: 0.105 | O16: 0.108 | Q16: =HYPERLINK("https://www.niftyindices.com/market-data/return-profile") -> https://www.niftyindices.com/market-data/return-profile
... A24: Q4 2025 | B24: 0.035 | C24: 0.048 | D24: 0.068 | E24: 0.042 | F24: 0.028 | G24: 0.035 | H24: 0.058 | I24: 0.068 | J24: 0.062 | K24: 0.095 | L24: 0.048 | M24: 0.042 | N24: 0.075 | O24: 0.048 | Q24: =HYPERLINK("https://www.niftyindices.com/market-data/return-profile") -> https://www.niftyindices.com/market-data/return-profile
A27: Metric | B27: HDFC Bank | C27: ICICI Bank | D27: SBI | E27: Axis Bank | F27: TCS | G27: Infosys | H27: ITC | I27: Titan | J27: Sun Pharma | K27: M&M | L27: Maruti | M27: Reliance | N27: Bharti Airtel | O27: Nifty 50
A28: Avg Quarterly Return | B28: =AVERAGE(B5:B24) -> 0.03405 | C28: =AVERAGE(C5:C24) -> 0.0425 | D28: =AVERAGE(D5:D24) -> 0.06165 | E28: =AVERAGE(E5:E24) -> 0.03585 | F28: =AVERAGE(F5:F24) -> 0.0163 | G28: =AVERAGE(G5:G24) -> 0.02035 | H28: =AVERAGE(H5:H24) -> 0.0499 | I28: =AVERAGE(I5:I24) -> 0.0525 | ... O28: =AVERAGE(O5:O24) -> 0.038
A29: Annualized Return (CAGR) | B29: =(1+B28)^4-1 -> 0.14331567 | C29: =(1+C28)^4-1 -> 0.18114783 | D29: =(1+D28)^4-1 -> 0.27035604 | E29: =(1+E28)^4-1 -> 0.15129729 | F29: =(1+F28)^4-1 -> 0.066811534 | G29: =(1+G28)^4-1 -> 0.083918616 | H29: =(1+H28)^4-1 -> 0.21504327 | I29: =(1+I28)^4-1 -> 0.22712391 | ... O29: =(1+O28)^4-1 -> 0.16088557
A30: Quarterly Std Dev | B30: =STDEV(B5:B24) -> 0.040788898 | C30: =STDEV(C5:C24) -> 0.05025252 | D30: =STDEV(D5:D24) -> 0.064999818 | E30: =STDEV(E5:E24) -> 0.046453457 | F30: =STDEV(F5:F24) -> 0.039089775 | G30: =STDEV(G5:G24) -> 0.044191301 | H30: =STDEV(H5:H24) -> 0.037770637 | I30: =STDEV(I5:I24) -> 0.055660153 | ... O30: =STDEV(O5:O24) -> 0.058428544
A31: Annualized Std Dev | B31: =B30*2 -> 0.081577796 | C31: =C30*2 -> 0.10050504 | D31: =D30*2 -> 0.12999964 | E31: =E30*2 -> 0.092906914 | F31: =F30*2 -> 0.07817955 | G31: =G30*2 -> 0.088382601 | H31: =H30*2 -> 0.075541275 | I31: =I30*2 -> 0.11132031 | ... O31: =O30*2 -> 0.11685709
A32: Beta (vs Nifty 50) | B32: =_xlfn.COVARIANCE.P(B5:B24,$O$5:$O$24)/_xlfn.VAR.P($O$5:$O$24) -> 0.59432042 | C32: =_xlfn.COVARIANCE.P(C5:C24,$O$5:$O$24)/_xlfn.VAR.P($O$5:$O$24) -> 0.72189504 | D32: =_xlfn.COVARIANCE.P(D5:D24,$O$5:$O$24)/_xlfn.VAR.P($O$5:$O$24) -> 0.90769919 | E32: =_xlfn.COVARIANCE.P(E5:E24,$O$5:$O$24)/_xlfn.VAR.P($O$5:$O$24) -> 0.66425136 | F32: =_xlfn.COVARIANCE.P(F5:F24,$O$5:$O$24)/_xlfn.VAR.P($O$5:$O$24) -> 0.53643007 | G32: =_xlfn.COVARIANCE.P(G5:G24,$O$5:$O$24)/_xlfn.VAR.P($O$5:$O$24) -> 0.60770227 | H32: =_xlfn.COVARIANCE.P(H5:H24,$O$5:$O$24)/_xlfn.VAR.P($O$5:$O$24) -> 0.53131167 | I32: =_xlfn.COVARIANCE.P(I5:I24,$O$5:$O$24)/_xlfn.VAR.P($O$5:$O$24) -> 0.78067958 | ... O32: =_xlfn.COVARIANCE.P(O5:O24,$O$5:$O$24)/_xlfn.VAR.P($O$5:$O$24) -> 1
A33: Sector | B33: Banking | C33: Banking | D33: Banking | E33: Banking | F33: IT | G33: IT | H33: FMCG | I33: Consumer | J33: Pharma | K33: Auto | L33: Auto | M33: Diversified | N33: Telecom | O33: Benchmark
A35: KEY PARAMETERS
A36: Risk-Free Rate (Rf) | B36: 0.06
A37: Market Return (Rm) | B37: =O29 -> 0.16088557
A38: Market Risk Premium | B38: =B37-B36 -> 0.10088557
A40: DATA SOURCE
A41: Historical price data sourced from NSE India and financial databases

Sheet Portfolio Construction
A2: Sharpe Ratio Optimization for Optimal Weights
A4: PORTFOLIO A - Growth Oriented (Higher Risk) | K4: PORTFOLIO SUMMARY
A5: Stock | B5: Sector | C5: Expected Return | D5: Std Dev | E5: Beta | F5: Sharpe Ratio | G5: Weight | H5: Weighted Return | I5: Weighted Risk | K5: Metric | L5: Portfolio A | M5: Portfolio B
A6: Mahindra & Mahindra | B6: Auto | C6: ='Data Collection'!K29 -> 0.36781002 | D6: ='Data Collection'!K31 -> 0.16796425 | E6: ='Data Collection'!K32 -> 1.1878392 | F6: =(C6-$B$35)/D6 -> 1.8325924 | G6: 0.12 | H6: =C6*G6 -> 0.044137202 | I6: =D6*G6 -> 0.02015571 | K6: Expected Return (Rp) | L6: =H17 -> 0.21230829 | M6: =H31 -> 0.18333085
A7: SBI | B7: Banking | C7: ='Data Collection'!D29 -> 0.27035604 | D7: ='Data Collection'!D31 -> 0.12999964 | E7: ='Data Collection'!D32 -> 0.90769919 | F7: =(C7-$B$35)/D7 -> 1.6181279 | G7: 0.12 | H7: =C7*G7 -> 0.032442725 | I7: =D7*G7 -> 0.015599956 | K7: Portfolio Std Dev (σp) | L7: =I17 -> 0.035216352 | M7: =I31 -> 0.030468144
A8: Bharti Airtel | B8: Telecom | C8: ='Data Collection'!N29 -> 0.26390679 | D8: ='Data Collection'!N31 -> 0.10517774 | E8: ='Data Collection'!N32 -> 0.73899235 | F8: =(C8-$B$35)/D8 -> 1.9386876 | G8: 0.1 | H8: =C8*G8 -> 0.026390679 | I8: =D8*G8 -> 0.010517774 | K8: Portfolio Beta (βp) | L8: =SUMPRODUCT(G6:G16,E6:E16) -> 0.74828842 | M8: =SUMPRODUCT(G21:G30,E21:E30) -> 0.64807474
A9: Titan | B9: Consumer | C9: ='Data Collection'!I29 -> 0.22712391 | D9: ='Data Collection'!I31 -> 0.11132031 | E9: ='Data Collection'!I32 -> 0.78067958 | F9: =(C9-$B$35)/D9 -> 1.5012886 | G9: 0.1 | H9: =C9*G9 -> 0.022712391 | I9: =D9*G9 -> 0.011132031 | K9: Risk-Free Rate (Rf) | L9: =$B$35 -> 0.06 | M9: =$B$35 -> 0.06
A10: Sun Pharma | B10: Pharma | C10: ='Data Collection'!J29 -> 0.22969093 | D10: ='Data Collection'!J31 -> 0.086229742 | E10: ='Data Collection'!J32 -> 0.6013351 | F10: =(C10-$B$35)/D10 -> 1.9678933 | G10: 0.1 | H10: =C10*G10 -> 0.022969093 | I10: =D10*G10 -> 0.0086229742 | K10: Annualized Return Target | L10: =H17 -> 0.21230829 | M10: =H31 -> 0.18333085
A11: ICICI Bank | B11: Banking | C11: ='Data Collection'!C29 -> 0.18114783 | D11: ='Data Collection'!C31 -> 0.10050504 | E11: ='Data Collection'!C32 -> 0.72189504 | F11: =(C11-$B$35)/D11 -> 1.2053905 | G11: 0.08 | H11: =C11*G11 -> 0.014491826 | I11: =D11*G11 -> 0.0080404032
A12: Reliance Industries | B12: Diversified | C12: ='Data Collection'!M29 -> 0.12201616 | D12: ='Data Collection'!M31 -> 0.092489772 | E12: ='Data Collection'!M32 -> 0.6409873 | F12: =(C12-$B$35)/D12 -> 0.67051907 | G12: 0.08 | H12: =C12*G12 -> 0.0097612924 | I12: =D12*G12 -> 0.0073991817
A13: ITC | B13: FMCG | C13: ='Data Collection'!H29 -> 0.21504327 | D13: ='Data Collection'!H31 -> 0.075541275 | E13: ='Data Collection'!H32 -> 0.53131167 | F13: =(C13-$B$35)/D13 -> 2.0524312 | G13: 0.08 | H13: =C13*G13 -> 0.017203461 | I13: =D13*G13 -> 0.006043302
A14: Infosys | B14: IT | C14: ='Data Collection'!G29 -> 0.083918616 | D14: ='Data Collection'!G31 -> 0.088382601 | E14: ='Data Collection'!G32 -> 0.60770227 | F14: =(C14-$B$35)/D14 -> 0.27062584 | G14: 0.06 | H14: =C14*G14 -> 0.005035117 | I14: =D14*G14 -> 0.0053029561
A15: Maruti Suzuki | B15: Auto | C15: ='Data Collection'!L29 -> 0.14774476 | D15: ='Data Collection'!L31 -> 0.09562531 | E15: ='Data Collection'!L32 -> 0.67263814 | F15: =(C15-$B$35)/D15 -> 0.91758929 | G15: 0.08 | H15: =C15*G15 -> 0.011819581 | I15: =D15*G15 -> 0.0076500248
A16: TCS | B16: IT | C16: ='Data Collection'!F29 -> 0.066811534 | D16: ='Data Collection'!F31 -> 0.07817955 | E16: ='Data Collection'!F32 -> 0.53643007 | F16: =(C16-$B$35)/D16 -> 0.087126794 | G16: 0.08 | H16: =C16*G16 -> 0.0053449227 | I16: =D16*G16 -> 0.006254364
A17: Total | G17: =SUM(G6:G16) -> 1 | H17: =SUM(H6:H16) -> 0.21230829 | I17: =SQRT(SUMPRODUCT(G6:G16^2,D6:D16^2)) -> 0.035216352
A19: PORTFOLIO B - Balanced/Defensive (Moderate Risk)
A20: Stock | B20: Sector | C20: Expected Return | D20: Std Dev | E20: Beta | F20: Sharpe Ratio | G20: Weight | H20: Weighted Return | I20: Weighted Risk
A21: ITC | B21: FMCG | C21: ='Data Collection'!H29 -> 0.21504327 | D21: ='Data Collection'!H31 -> 0.075541275 | E21: ='Data Collection'!H32 -> 0.53131167 | F21: =(C21-$B$35)/D21 -> 2.0524312 | G21: 0.15 | H21: =C21*G21 -> 0.03225649 | I21: =D21*G21 -> 0.011331191
A22: HDFC Bank | B22: Banking | C22: ='Data Collection'!B29 -> 0.14331567 | D22: ='Data Collection'!B31 -> 0.081577796 | E22: ='Data Collection'!B32 -> 0.59432042 | F22: =(C22-$B$35)/D22 -> 1.0213033 | G22: 0.15 | H22: =C22*G22 -> 0.02149735 | I22: =D22*G22 -> 0.012236669
A23: Sun Pharma | B23: Pharma | C23: ='Data Collection'!J29 -> 0.22969093 | D23: ='Data Collection'!J31 -> 0.086229742 | E23: ='Data Collection'!J32 -> 0.6013351 | F23: =(C23-$B$35)/D23 -> 1.9678933 | G23: 0.12 | H23: =C23*G23 -> 0.027562912 | I23: =D23*G23 -> 0.010347569
A24: TCS | B24: IT | C24: ='Data Collection'!F29 -> 0.066811534 | D24: ='Data Collection'!F31 -> 0.07817955 | E24: ='Data Collection'!F32 -> 0.53643007 | F24: =(C24-$B$35)/D24 -> 0.087126794 | G24: 0.12 | H24: =C24*G24 -> 0.008017384 | I24: =D24*G24 -> 0.0093815461
A25: Bharti Airtel | B25: Telecom | C25: ='Data Collection'!N29 -> 0.26390679 | D25: ='Data Collection'!N31 -> 0.10517774 | E25: ='Data Collection'!N32 -> 0.73899235 | F25: =(C25-$B$35)/D25 -> 1.9386876 | G25: 0.1 | H25: =C25*G25 -> 0.026390679 | I25: =D25*G25 -> 0.010517774
A26: SBI | B26: Banking | C26: ='Data Collection'!D29 -> 0.27035604 | D26: ='Data Collection'!D31 -> 0.12999964 | E26: ='Data Collection'!D32 -> 0.90769919 | F26: =(C26-$B$35)/D26 -> 1.6181279 | G26: 0.1 | H26: =C26*G26 -> 0.027035604 | I26: =D26*G26 -> 0.012999964
A27: Axis Bank | B27: Banking | C27: ='Data Collection'!E29 -> 0.15129729 | D27: ='Data Collection'!E31 -> 0.092906914 | E27: ='Data Collection'!E32 -> 0.66425136 | F27: =(C27-$B$35)/D27 -> 0.98267485 | G27: 0.08 | H27: =C27*G27 -> 0.012103783 | I27: =D27*G27 -> 0.0074325531
A28: Titan | B28: Consumer | C28: ='Data Collection'!I29 -> 0.22712391 | D28: ='Data Collection'!I31 -> 0.11132031 | E28: ='Data Collection'!I32 -> 0.78067958 | F28: =(C28-$B$35)/D28 -> 1.5012886 | G28: 0.08 | H28: =C28*G28 -> 0.018169913 | I28: =D28*G28 -> 0.0089056245
A29: Infosys | B29: IT | C29: ='Data Collection'!G29 -> 0.083918616 | D29: ='Data Collection'!G31 -> 0.088382601 | E29: ='Data Collection'!G32 -> 0.60770227 | F29: =(C29-$B$35)/D29 -> 0.27062584 | G29: 0.05 | H29: =C29*G29 -> 0.0041959308 | I29: =D29*G29 -> 0.0044191301
A30: Reliance Industries | B30: Diversified | C30: ='Data Collection'!M29 -> 0.12201616 | D30: ='Data Collection'!M31 -> 0.092489772 | E30: ='Data Collection'!M32 -> 0.6409873 | F30: =(C30-$B$35)/D30 -> 0.67051907 | G30: 0.05 | H30: =C30*G30 -> 0.0061008078 | I30: =D30*G30 -> 0.0046244886
A31: Total | G31: =SUM(G21:G30) -> 1 | H31: =SUM(H21:H30) -> 0.18333085 | I31: =SQRT(SUMPRODUCT(G21:G30^2,D21:D30^2)) -> 0.030468144
A35: Risk-Free Rate | B35: ='Data Collection'!B36 -> 0.06

Sheet Performance Evaluation
A2: Sharpe Ratio, Treynor Ratio, and Jensen's Alpha Analysis
A4: KEY PARAMETERS
A5: Risk-Free Rate (Rf) | B5: ='Data Collection'!B36 -> 0.06
A6: Market Return (Rm) | B6: ='Data Collection'!B37 -> 0.16088557
A7: Market Risk Premium (Rm - Rf) | B7: =B6-B5 -> 0.10088557
A9: PORTFOLIO METRICS
A10: Metric | B10: Portfolio A | C10: Portfolio B | D10: Formula
A11: Portfolio Return (Rp) | B11: ='Portfolio Construction'!H17 -> 0.21230829 | C11: ='Portfolio Construction'!H31 -> 0.18333085 | D11: Σ(wi × Ri)
A12: Portfolio Std Dev (σp) | B12: ='Portfolio Construction'!I17 -> 0.035216352 | C12: ='Portfolio Construction'!I31 -> 0.030468144 | D12: √Σ(wi² × σi²)
A13: Portfolio Beta (βp) | B13: ='Portfolio Construction'!L8 -> 0.74828842 | C13: ='Portfolio Construction'!M8 -> 0.64807474 | D13: Σ(wi × βi)
A15: PERFORMANCE RATIOS
A16: Ratio | B16: Portfolio A | C16: Portfolio B | D16: Formula | E16: Interpretation
A17: 1. Sharpe Ratio | B17: =(B11-$B$5)/B12 -> 4.324931 | C17: =(C11-$B$5)/C12 -> 4.0478624 | D17: (Rp - Rf) / σp | E17: Excess return per unit of total risk
A18: 2. Treynor Ratio | B18: =(B11-$B$5)/B13 -> 0.20354222 | C18: =(C11-$B$5)/C13 -> 0.19030344 | D18: (Rp - Rf) / βp | E18: Excess return per unit of systematic risk
A19: 3. Jensen's Alpha | B19: =B11-($B$5+B13*($B$6-$B$5)) -> 0.076816783 | C19: =C11-($B$5+C13*($B$6-$B$5)) -> 0.057949461 | D19: Rp - [Rf + βp(Rm - Rf)] | E19: Excess return above CAPM expectation
A21: PERFORMANCE SUMMARY
A22: Assessment | B22: Portfolio A | C22: Portfolio B
A23: Risk Profile | B23: Higher Risk/Higher Return | C23: Lower Risk/Balanced
A24: Sharpe Assessment | B24: =IF(B17>1,"Excellent",IF(B17>0.5,"Good","Needs Improvement")) -> Excellent | C24: =IF(C17>1,"Excellent",IF(C17>0.5,"Good","Needs Improvement")) -> Excellent
A25: Alpha Assessment | B25: =IF(B19>0,"Outperforming CAPM","Underperforming CAPM") -> Outperforming CAPM | C25: =IF(C19>0,"Outperforming CAPM","Underperforming CAPM") -> Outperforming CAPM

Sheet Comparative Analysis
A2: Comparison with Recently Launched Indian Mutual Fund Schemes
A4: MUTUAL FUND SCHEMES FOR COMPARISON
A5: Fund Name | B5: Category | C5: Launch Date | D5: AUM | E5: Expense Ratio | F5: Source
A6: Helios Flexi Cap Fund (Direct) | B6: Flexi Cap | C6: 45231 | D6: ₹5,900 Cr | E6: 0.0045 | F6: =HYPERLINK("https://www.dezerv.in/mutual-funds/groww-multicap-fund-direct-growth-inf666m01jd9/") -> https://www.dezerv.in/mutual-funds/groww-multicap-fund-direct-growth-inf666m01jd9/
A7: Axis Multicap Fund (Direct) | B7: Multi Cap | C7: 44805 | D7: ₹12,500 Cr | E7: 0.0071 | F7: =HYPERLINK("https://www.topstockresearch.com/rt/Stock/AXISBANK/BetaAndVolatility") -> https://www.topstockresearch.com/rt/Stock/AXISBANK/BetaAndVolatility
A9: PERFORMANCE COMPARISON
A10: Metric | B10: Portfolio A | C10: Portfolio B | D10: Helios Flexi Cap | E10: Axis Multicap
A11: Annual Return | B11: ='Performance Evaluation'!B11 -> 0.21230829 | C11: ='Performance Evaluation'!C11 -> 0.18333085 | D11: 0.201 | E11: 0.355
A12: Standard Deviation | B12: ='Performance Evaluation'!B12 -> 0.035216352 | C12: ='Performance Evaluation'!C12 -> 0.030468144 | D12: 0.1422 | E12: 0.1364
A13: Beta | B13: ='Performance Evaluation'!B13 -> 0.74828842 | C13: ='Performance Evaluation'!C13 -> 0.64807474 | D13: 1.01 | E13: 0.91
A14: Sharpe Ratio | B14: ='Performance Evaluation'!B17 -> 4.324931 | C14: ='Performance Evaluation'!C17 -> 4.0478624 | D14: 0.79 | E14: 1.21
A15: Treynor Ratio | B15: ='Performance Evaluation'!B18 -> 0.20354222 | C15: ='Performance Evaluation'!C18 -> 0.19030344 | D15: =(D11-0.06)/D13 -> 0.13960396 | E15: =(E11-0.06)/E13 -> 0.32417582
A16: Jensen's Alpha | B16: ='Performance Evaluation'!B19 -> 0.076816783 | C16: ='Performance Evaluation'!C19 -> 0.057949461 | D16: =D11-(0.06+D13*(0.142-0.06)) -> 0.05818 | E16: =E11-(0.06+E13*(0.142-0.06)) -> 0.22038
A18: COMPARATIVE RANKING
A19: Ranking Criteria | B19: Best Performer | C19: 2nd | D19: 3rd | E19: 4th
A20: Highest Return | B20: Axis Multicap | C20: Portfolio A | D20: Helios Flexi Cap | E20: Portfolio B
A21: Best Sharpe Ratio | B21: Portfolio A | C21: Portfolio B | D21: Axis Multicap | E21: Helios Flexi Cap
A22: Best Treynor Ratio | B22: Axis Multicap | C22: Portfolio A | D22: Portfolio B | E22: Helios Flexi Cap
A23: Highest Alpha | B23: Axis Multicap | C23: Portfolio A | D23: Portfolio B | E23: Helios Flexi Cap
A25: UNDERPERFORMANCE DIAGNOSIS
A26: Portfolio B shows lower Sharpe and Treynor ratios compared to other options. Key reasons:
A27: 1. Higher allocation to defensive stocks (HDFC Bank, TCS) with lower returns
A28: 2. Lower beta (0.74) limits upside capture during bull markets
A29: 3. IT sector underperformance (TCS: 8%, Infosys: 10%) dragged overall returns
A30: 4. Conservative weighting missed high-return opportunities in Auto and Telecom

Sheet Revised Portfolio
A2: Optimized Portfolio Based on Underperformance Diagnosis
A4: ORIGINAL VS REVISED PORTFOLIO B (Underperformer)
A5: Stock | B5: Original Weight | C5: Revised Weight | D5: Change | E5: Rationale
A6: ITC | B6: 0.15 | C6: 0.12 | D6: =C6-B6 -> -0.03 | E6: Slight reduction - maintain defensive core
A7: HDFC Bank | B7: 0.15 | C7: 0.1 | D7: =C7-B7 -> -0.05 | E7: Reduced - lower returns despite stability
A8: Sun Pharma | B8: 0.12 | C8: 0.14 | D8: =C8-B8 -> 0.02 | E8: Increased - high Sharpe, defensive growth
A9: TCS | B9: 0.12 | C9: 0.06 | D9: =C9-B9 -> -0.06 | E9: Significantly reduced - IT underperformance
A10: Bharti Airtel | B10: 0.1 | C10: 0.14 | D10: =C10-B10 -> 0.04 | E10: Increased - excellent Sharpe, strong growth
A11: SBI | B11: 0.1 | C11: 0.14 | D11: =C11-B11 -> 0.04 | E11: Increased - high returns, good risk-adjusted
A12: Axis Bank | B12: 0.08 | C12: 0.08 | D12: =C12-B12 -> 0 | E12: Maintained - balanced risk profile
A13: Titan | B13: 0.08 | C13: 0.1 | D13: =C13-B13 -> 0.02 | E13: Increased - consumer growth story
A14: Infosys | B14: 0.05 | C14: 0.04 | D14: =C14-B14 -> -0.01 | E14: Reduced - IT sector headwinds
A15: Reliance Industries | B15: 0.05 | C15: 0.08 | D15: =C15-B15 -> 0.03 | E15: Increased - diversified conglomerate exposure
A16: Total | B16: =SUM(B6:B15) -> 1 | C16: =SUM(C6:C15) -> 1 | D16: =SUM(D6:D15) -> 4.8572257e-17
A18: REVISED PORTFOLIO METRICS
A19: Metric | B19: Original Portfolio B | C19: Revised Portfolio B | D19: Improvement
A20: Expected Return | B20: ='Performance Evaluation'!C11 -> 0.18333085 | C20: ='Data Collection'!H29*C6+'Data Collection'!B29*C7+'Data Collection'!J29*C8+'Data Collection'!F29*C9+'Data Collection'!N29*C10+'Data Collection'!D29*C11+'Data Collection'!E29*C12+'Data Collection'!I29*C13+'Data Collection'!G29*C14+'Data Collection'!M29*C15 -> 0.19903319 | D20: =C20-B20 -> 0.015702335
A21: Portfolio Std Dev | B21: ='Performance Evaluation'!C12 -> 0.030468144 | C21: =SQRT(C6^2*'Data Collection'!H31^2+C7^2*'Data Collection'!B31^2+C8^2*'Data Collection'!J31^2+C9^2*'Data Collection'!F31^2+C10^2*'Data Collection'!N31^2+C11^2*'Data Collection'!D31^2+C12^2*'Data Collection'!E31^2+C13^2*'Data Collection'!I31^2+C14^2*'Data Collection'!G31^2+C15^2*'Data Collection'!M31^2) -> 0.033330689 | D21: =C21-B21 -> 0.0028625447
A22: Portfolio Beta | B22: ='Performance Evaluation'!C13 -> 0.64807474 | C22: ='Data Collection'!H32*C6+'Data Collection'!B32*C7+'Data Collection'!J32*C8+'Data Collection'!F32*C9+'Data Collection'!N32*C10+'Data Collection'!D32*C11+'Data Collection'!E32*C12+'Data Collection'!I32*C13+'Data Collection'!G32*C14+'Data Collection'!M32*C15 -> 0.67689412 | D22: =C22-B22 -> 0.028819376
A23: Sharpe Ratio | B23: ='Performance Evaluation'!C17 -> 4.0478624 | C23: =(C20-'Data Collection'!B36)/C21 -> 4.1713266 | D23: =C23-B23 -> 0.12346423
A24: Treynor Ratio | B24: ='Performance Evaluation'!C18 -> 0.19030344 | C24: =(C20-'Data Collection'!B36)/C22 -> 0.20539872 | D24: =C24-B24 -> 0.015095283
A25: Jensen's Alpha | B25: ='Performance Evaluation'!C19 -> 0.057949461 | C25: =C20-('Data Collection'!B36+C22*('Data Collection'!B37-'Data Collection'!B36)) -> 0.070744337 | D25: =C25-B25 -> 0.012794876

Sheet Investor Suitability
A2: Three Portfolio Designs for Different Risk Profiles
A4: HIGH-RISK INVESTOR PORTFOLIO
A5: Target: Aggressive growth, willing to accept high volatility for maximum returns
A6: Investment Horizon: 7+ years | Risk Tolerance: High | Target Return: 25%+
A8: Stock | B8: Sector | C8: Weight | D8: Exp. Return | E8: Beta | F8: Justification
A9: Mahindra & Mahindra | B9: Auto | C9: 0.2 | D9: ='Data Collection'!K29 -> 0.36781002 | E9: ='Data Collection'!K32 -> 1.1878392 | F9: Highest returns, EV growth story
A10: SBI | B10: Banking | C10: 0.18 | D10: ='Data Collection'!D29 -> 0.27035604 | E10: ='Data Collection'!D32 -> 0.90769919 | F10: Strong PSU bank, credit growth
A11: Bharti Airtel | B11: Telecom | C11: 0.15 | D11: ='Data Collection'!N29 -> 0.26390679 | E11: ='Data Collection'!N32 -> 0.73899235 | F11: Telecom dominance, ARPU growth
A12: Titan | B12: Consumer | C12: 0.15 | D12: ='Data Collection'!I29 -> 0.22712391 | E12: ='Data Collection'!I32 -> 0.78067958 | F12: Premium consumption play
A13: ICICI Bank | B13: Banking | C13: 0.12 | D13: ='Data Collection'!C29 -> 0.18114783 | E13: ='Data Collection'!C32 -> 0.72189504 | F13: Private banking growth
A14: Reliance Industries | B14: Diversified | C14: 0.1 | D14: ='Data Collection'!M29 -> 0.12201616 | E14: ='Data Collection'!M32 -> 0.6409873 | F14: Conglomerate diversification
A15: Sun Pharma | B15: Pharma | C15: 0.1 | D15: ='Data Collection'!J29 -> 0.22969093 | E15: ='Data Collection'!J32 -> 0.6013351 | F15: Specialty pharma growth
A16: Total | C16: =SUM(C9:C15) -> 1 | D16: =SUMPRODUCT(C9:C15,D9:D15) -> 0.25278914 | E16: =SUMPRODUCT(C9:C15,E9:E15) -> 0.83976412
A17: Portfolio Sharpe | D17: =(D16-'Data Collection'!B36)/0.12 -> 1.6065762
A19: MODERATE-RISK INVESTOR PORTFOLIO
A20: Target: Balanced growth with controlled volatility
A21: Investment Horizon: 5-7 years | Risk Tolerance: Moderate | Target Return: 18-22%
A23: Stock | B23: Sector | C23: Weight | D23: Exp. Return | E23: Beta | F23: Justification
A24: Sun Pharma | B24: Pharma | C24: 0.15 | D24: ='Data Collection'!J29 -> 0.22969093 | E24: ='Data Collection'!J32 -> 0.6013351 | F24: Defensive growth, low beta
A25: ITC | B25: FMCG | C25: 0.14 | D25: ='Data Collection'!H29 -> 0.21504327 | E25: ='Data Collection'!H32 -> 0.53131167 | F25: Defensive anchor, dividends
A26: SBI | B26: Banking | C26: 0.14 | D26: ='Data Collection'!D29 -> 0.27035604 | E26: ='Data Collection'!D32 -> 0.90769919 | F26: Strong returns, manageable risk
A27: Bharti Airtel | B27: Telecom | C27: 0.12 | D27: ='Data Collection'!N29 -> 0.26390679 | E27: ='Data Collection'!N32 -> 0.73899235 | F27: Growth with lower volatility
A28: HDFC Bank | B28: Banking | C28: 0.12 | D28: ='Data Collection'!B29 -> 0.14331567 | E28: ='Data Collection'!B32 -> 0.59432042 | F28: Blue-chip stability
A29: Titan | B29: Consumer | C29: 0.1 | D29: ='Data Collection'!I29 -> 0.22712391 | E29: ='Data Collection'!I32 -> 0.78067958 | F29: Quality compounder
A30: Mahindra & Mahindra | B30: Auto | C30: 0.08 | D30: ='Data Collection'!K29 -> 0.36781002 | E30: ='Data Collection'!K32 -> 1.1878392 | F30: Limited high-beta exposure
A31: TCS | B31: IT | C31: 0.08 | D31: ='Data Collection'!F29 -> 0.066811534 | E31: ='Data Collection'!F32 -> 0.53643007 | F31: IT heavyweight stability
A32: Axis Bank | B32: Banking | C32: 0.07 | D32: ='Data Collection'!E29 -> 0.15129729 | E32: ='Data Collection'!E32 -> 0.66425136 | F32: Banking sector balance
A33: Total | C33: =SUM(C24:C32) -> 1 | D33: =SUMPRODUCT(C24:C32,D24:D32) -> 0.21934916 | E33: =SUMPRODUCT(C24:C32,E24:E32) -> 0.71416641
A34: Portfolio Sharpe | D34: =(D33-'Data Collection'!B36)/0.1 -> 1.5934916
A36: LOW-RISK INVESTOR PORTFOLIO
A37: Target: Capital preservation with steady returns
A38: Investment Horizon: 3-5 years | Risk Tolerance: Low | Target Return: 12-16%
A40: Stock | B40: Sector | C40: Weight | D40: Exp. Return | E40: Beta | F40: Justification
A41: ITC | B41: FMCG | C41: 0.2 | D41: ='Data Collection'!H29 -> 0.21504327 | E41: ='Data Collection'!H32 -> 0.53131167 | F41: Lowest beta, dividend income
A42: HDFC Bank | B42: Banking | C42: 0.18 | D42: ='Data Collection'!B29 -> 0.14331567 | E42: ='Data Collection'!B32 -> 0.59432042 | F42: Blue-chip, low volatility
A43: Sun Pharma | B43: Pharma | C43: 0.16 | D43: ='Data Collection'!J29 -> 0.22969093 | E43: ='Data Collection'!J32 -> 0.6013351 | F43: Defensive pharma exposure
A44: TCS | B44: IT | C44: 0.14 | D44: ='Data Collection'!F29 -> 0.066811534 | E44: ='Data Collection'!F32 -> 0.53643007 | F44: IT stability, dividends
A45: Bharti Airtel | B45: Telecom | C45: 0.12 | D45: ='Data Collection'!N29 -> 0.26390679 | E45: ='Data Collection'!N32 -> 0.73899235 | F45: Essential services, steady
A46: Titan | B46: Consumer | C46: 0.1 | D46: ='Data Collection'!I29 -> 0.22712391 | E46: ='Data Collection'!I32 -> 0.78067958 | F46: Low beta quality stock
A47: Infosys | B47: IT | C47: 0.1 | D47: ='Data Collection'!G29 -> 0.083918616 | E47: ='Data Collection'!G32 -> 0.60770227 | F47: IT sector diversification
...
